<!-- This URDF was automatically created by SolidWorks to URDF Exporter! Originally created by Stephen Brawner (brawner@gmail.com) 
     Commit Version: 1.6.0-4-g7f85cfe  Build Version: 1.6.7995.38578
     For more information, please see http://wiki.ros.org/sw_urdf_exporter -->
<robot
  name="gripper"
  xmlns:xacro="http://ros.org/wiki/xacro">

  <link
    name="end_base">
    <inertial>
      <origin xyz="0 0 0" rpy="0 0 0"/>
      <mass value="0.4"/>
      <inertia
        ixx="0.01"
        ixy="0.0"
        ixz="0.0"
        iyy="0.01"
        iyz="0.0"
        izz="0.01"/>
    </inertial>

    <visual>
      <origin
        xyz="0 0 0"
        rpy="0 0 0" />
      <geometry>
        <mesh
          filename="package://aligned_arm/meshes/end_base.STL" />
      </geometry>
      <material
        name="">
        <color
          rgba="0.792156862745098 0.819607843137255 0.933333333333333 1" />
      </material>
    </visual>
    <collision>
      <origin
        xyz="0 0 0"
        rpy="0 0 0" />
      <geometry>
        <mesh
          filename="package://aligned_arm/meshes/end_base.STL" />
      </geometry>
    </collision>
  </link>
  <!-- <joint
    name="end_joint"
    type="revolute">
    <origin
      xyz="0.0545990000041253 0.0259989999957502 0.0269999999957503"
      rpy="0.0529233606550124 0 0" />
    <parent
      link="wrist_Link" />
    <child
      link="end_base" />
    <axis
      xyz="-1 0 0" />
    <limit
      lower="-1.57"
      upper="1.57"
      effort="1"
      velocity="1" />
    <dynamics damping="0.5" friction="0.1"/>
  </joint> -->
  <link
    name="gear_right">
    <inertial>
      <origin xyz="0 0 0" rpy="0 0 0"/>
      <mass value="0.1"/>
      <inertia
        ixx="0.01"
        ixy="0.0"
        ixz="0.0"
        iyy="0.01"
        iyz="0.0"
        izz="0.01"/>
    </inertial>

    <visual>
      <origin
        xyz="0 0 0"
        rpy="0 0 0" />
      <geometry>
        <mesh
          filename="package://aligned_arm/meshes/gear_right.STL" />
      </geometry>
      <material
        name="">
        <color
          rgba="0.792156862745098 0.819607843137255 0.933333333333333 1" />
      </material>
    </visual>
    <collision>
      <origin
        xyz="0 0 0"
        rpy="0 0 0" />
      <geometry>
        <mesh
          filename="package://aligned_arm/meshes/gear_right.STL" />
      </geometry>
    </collision>
  </link>
  <joint
    name="gear_right_joint"
    type="revolute">
    <origin
      xyz="0.03 -0.015741 0.0043"
      rpy="0 0 -0.60373" />
    <parent
      link="end_base" />
    <child
      link="gear_right" />
    <axis
      xyz="0 0 -1" />
    <limit
      lower="-1.57"
      upper="1.57"
      effort="1"
      velocity="1" />
    <dynamics damping="0.5" friction="0.1"/>
  </joint>
  <link
    name="finger_right">
    <inertial>
      <origin xyz="0 0 0" rpy="0 0 0"/>
      <mass value="0.1"/>
      <inertia
        ixx="0.01"
        ixy="0.0"
        ixz="0.0"
        iyy="0.01"
        iyz="0.0"
        izz="0.01"/>
    </inertial>

    <visual>
      <origin
        xyz="0 0 0"
        rpy="0 0 0" />
      <geometry>
        <mesh
          filename="package://aligned_arm/meshes/finger_right.STL" />
      </geometry>
      <material
        name="">
        <color
          rgba="0.792156862745098 0.819607843137255 0.933333333333333 1" />
      </material>
    </visual>
    <collision>
      <origin
        xyz="0 0 0"
        rpy="0 0 0" />
      <geometry>
        <mesh
          filename="package://aligned_arm/meshes/finger_right.STL" />
      </geometry>
    </collision>
  </link>
  <joint
    name="finger_right_joint"
    type="revolute">
    <origin
      xyz="0.030762 0 0.0025"
      rpy="0 0 0.98133" />
    <parent
      link="gear_right" />
    <child
      link="finger_right" />
    <axis
      xyz="0 0 1" />
    <limit
      lower="-1.57"
      upper="1.57"
      effort="1"
      velocity="1" />
    <mimic
      joint="gear_right_joint"
      multiplier="1"
      offset="0" />
    <dynamics damping="0.5" friction="0.1"/>
  </joint>
  <link
    name="gear_left">
    <inertial>
      <origin xyz="0 0 0" rpy="0 0 0"/>
      <mass value="0.1"/>
      <inertia
        ixx="0.01"
        ixy="0.0"
        ixz="0.0"
        iyy="0.01"
        iyz="0.0"
        izz="0.01"/>
    </inertial>

    <visual>
      <origin
        xyz="0 0 0"
        rpy="0 0 0" />
      <geometry>
        <mesh
          filename="package://aligned_arm/meshes/gear_left.STL" />
      </geometry>
      <material
        name="">
        <color
          rgba="0.792156862745098 0.819607843137255 0.933333333333333 1" />
      </material>
    </visual>
    <collision>
      <origin
        xyz="0 0 0"
        rpy="0 0 0" />
      <geometry>
        <mesh
          filename="package://aligned_arm/meshes/gear_left.STL" />
      </geometry>
    </collision>
  </link>
  <joint
    name="gear_left_joint"
    type="revolute">
    <origin
      xyz="0.0305 0.01226 0.0068"
      rpy="0 0 0.3732" />
    <parent
      link="end_base" />
    <child
      link="gear_left" />
    <axis
      xyz="0 0 -1" />
    <limit
      lower="-1.57"
      upper="1.57"
      effort="1"
      velocity="1" />
    <mimic
      joint="gear_right_joint"
      multiplier="-1"
      offset="0" />
    <dynamics damping="0.5" friction="0.1"/>
  </joint>
  <link
    name="finger_left">
    <inertial>
      <origin xyz="0 0 0" rpy="0 0 0"/>
      <mass value="0.1"/>
      <inertia
        ixx="0.01"
        ixy="0.0"
        ixz="0.0"
        iyy="0.01"
        iyz="0.0"
        izz="0.01"/>
    </inertial>

    <visual>
      <origin
        xyz="0 0 0"
        rpy="0 0 0" />
      <geometry>
        <mesh
          filename="package://aligned_arm/meshes/finger_left.STL" />
      </geometry>
      <material
        name="">
        <color
          rgba="0.792156862745098 0.819607843137255 0.933333333333333 1" />
      </material>
    </visual>
    <collision>
      <origin
        xyz="0 0 0"
        rpy="0 0 0" />
      <geometry>
        <mesh
          filename="package://aligned_arm/meshes/finger_left.STL" />
      </geometry>
    </collision>
  </link>
  <joint
    name="finger_left_joint"
    type="revolute">
    <origin
      xyz="0.030762 0 0"
      rpy="0 0 -0.68869" />
    <parent
      link="gear_left" />
    <child
      link="finger_left" />
    <axis
      xyz="0 0 1" />
    <limit
      lower="-1.57"
      upper="1.57"
      effort="1"
      velocity="1" />
    <mimic
      joint="gear_left_joint"
      multiplier="1"
      offset="0" />
    <dynamics damping="0.5" friction="0.1"/>
  </joint>
  <link
    name="anchor_right">
    <inertial>
      <origin xyz="0 0 0" rpy="0 0 0"/>
      <mass value="0.1"/>
      <inertia
        ixx="0.01"
        ixy="0.0"
        ixz="0.0"
        iyy="0.01"
        iyz="0.0"
        izz="0.01"/>
    </inertial>

    <visual>
      <origin
        xyz="0 0 0"
        rpy="0 0 0" />
      <geometry>
        <mesh
          filename="package://aligned_arm/meshes/anchor_right.STL" />
      </geometry>
      <material
        name="">
        <color
          rgba="0.792156862745098 0.819607843137255 0.933333333333333 1" />
      </material>
    </visual>
    <collision>
      <origin
        xyz="0 0 0"
        rpy="0 0 0" />
      <geometry>
        <mesh
          filename="package://aligned_arm/meshes/anchor_right.STL" />
      </geometry>
    </collision>
  </link>
  <joint
    name="anchor_right_joint"
    type="revolute">
    <origin
      xyz="0.0525 -0.007 0.0068"
      rpy="0 0 -0.6321" />
    <parent
      link="end_base" />
    <child
      link="anchor_right" />
    <axis
      xyz="0 0 -1" />
    <limit
      lower="-1.57"
      upper="1.57"
      effort="1"
      velocity="1" />
    <mimic
      joint="gear_right_joint"
      multiplier="1"
      offset="0" />
    <dynamics damping="0.5" friction="0.1"/>
  </joint>
  <link
    name="anchor_left">
    <inertial>
      <origin xyz="0 0 0" rpy="0 0 0"/>
      <mass value="0.1"/>
      <inertia
        ixx="0.01"
        ixy="0.0"
        ixz="0.0"
        iyy="0.01"
        iyz="0.0"
        izz="0.01"/>
    </inertial>

    <visual>
      <origin
        xyz="0 0 0"
        rpy="0 0 0" />
      <geometry>
        <mesh
          filename="package://aligned_arm/meshes/anchor_left.STL" />
      </geometry>
      <material
        name="">
        <color
          rgba="0.792156862745098 0.819607843137255 0.933333333333333 1" />
      </material>
    </visual>
    <collision>
      <origin
        xyz="0 0 0"
        rpy="0 0 0" />
      <geometry>
        <mesh
          filename="package://aligned_arm/meshes/anchor_left.STL" />
      </geometry>
    </collision>
  </link>
  <joint
    name="anchor_left_joint"
    type="revolute">
    <origin
      xyz="0.0525 0.007 0.0068"
      rpy="0 0 0.31658" />
    <parent
      link="end_base" />
    <child
      link="anchor_left" />
    <axis
      xyz="0 0 -1" />
    <limit
      lower="-1.57"
      upper="1.57"
      effort="1"
      velocity="1" />
    <mimic
      joint="gear_left_joint"
      multiplier="1"
      offset="0" />
    <dynamics damping="0.5" friction="0.1"/>
  </joint>

  <link name="wrist_camera_link"/>
  <joint name="wrist_camera_joint" type="fixed">
    <parent link="end_base"/>
    <child link="wrist_camera_link"/>
    <origin xyz="0.05 0 0" rpy="0 0 0"/>
  </joint>

  <gazebo reference="wrist_camera_link">
    <sensor type="camera" name="wrist_camera">
      <always_on>true</always_on>
      <update_rate>30</update_rate>

      <camera>
        <horizontal_fov>1.047</horizontal_fov>
        <image>
          <width>640</width>
          <height>480</height>
          <format>R8G8B8</format>
        </image>
        <clip>
          <near>0.01</near>
          <far>10.0</far>
        </clip>
      </camera>

      <plugin name="gazebo_ros_camera" filename="libgazebo_ros_camera.so">
        <camera_name>wrist_camera</camera_name>
        <frame_name>wrist_camera_link</frame_name>
        <image_topic_name>image_raw</image_topic_name>
        <camera_info_topic_name>camera_info</camera_info_topic_name>
      </plugin>
    </sensor>
  </gazebo>

</robot>