<?xml version="1.0" encoding="utf-8"?>
<!-- This URDF was automatically created by SolidWorks to URDF Exporter! Originally created by Stephen Brawner (brawner@gmail.com) 
     Commit Version: 1.6.0-4-g7f85cfe  Build Version: 1.6.7995.38578
     For more information, please see http://wiki.ros.org/sw_urdf_exporter -->
<robot
  name="robotic_arm_6dof">
  <link
    name="base_link">
    <inertial>
      <origin
        xyz="-0.160748808307766 -0.00741797832213025 -0.088360649318168"
        rpy="0 0 0" />
      <mass
        value="0.0763754463040628" />
      <inertia
        ixx="4.23953757303269E-05"
        ixy="-9.86232282095576E-12"
        ixz="6.65031103528841E-08"
        iyy="1.87712760672681E-05"
        iyz="7.17319272491096E-08"
        izz="3.99044935666079E-05" />
    </inertial>
    <visual>
      <origin
        xyz="0 0 0"
        rpy="0 0 0" />
      <geometry>
        <mesh
          filename="package://robotic_arm_6dof/meshes/base_link.STL" />
      </geometry>
      <material
        name="">
        <color
          rgba="0.792156862745098 0.819607843137255 0.933333333333333 1" />
      </material>
    </visual>
    <collision>
      <origin
        xyz="0 0 0"
        rpy="0 0 0" />
      <geometry>
        <mesh
          filename="package://robotic_arm_6dof/meshes/base_link.STL" />
      </geometry>
    </collision>
  </link>
  <link
    name="base_rotator">
    <inertial>
      <origin
        xyz="0.0136091822020193 0.000265822789707187 0.0127057602834607"
        rpy="0 0 0" />
      <mass
        value="0.0393066448790151" />
      <inertia
        ixx="8.94291156894741E-06"
        ixy="-7.16990812231746E-08"
        ixz="6.78884235910539E-12"
        iyy="1.17467155572598E-05"
        iyz="-6.65028867021334E-08"
        izz="1.13233060126383E-05" />
    </inertial>
    <visual>
      <origin
        xyz="0 0 0"
        rpy="0 0 0" />
      <geometry>
        <mesh
          filename="package://robotic_arm_6dof/meshes/base_rotator.STL" />
      </geometry>
      <material
        name="">
        <color
          rgba="0.792156862745098 0.819607843137255 0.933333333333333 1" />
      </material>
    </visual>
    <collision>
      <origin
        xyz="0 0 0"
        rpy="0 0 0" />
      <geometry>
        <mesh
          filename="package://robotic_arm_6dof/meshes/base_rotator.STL" />
      </geometry>
    </collision>
  </link>
  <joint
    name="base_rotator_joint"
    type="continuous">
    <origin
      xyz="-0.15562 -0.016822 -0.042262"
      rpy="0 0 -0.28913" />
    <parent
      link="base_link" />
    <child
      link="base_rotator" />
    <axis
      xyz="0 0 -1" />
  </joint>
  <link
    name="shoulder_link">
    <inertial>
      <origin
        xyz="-0.00542737331091207 0.0207591340660911 0.0514605309104713"
        rpy="0 0 0" />
      <mass
        value="0.0144514859726596" />
      <inertia
        ixx="1.17337857012936E-05"
        ixy="1.61790596037335E-06"
        ixz="1.04410809662612E-12"
        iyy="5.96847210302326E-06"
        iyz="1.47468699935973E-12"
        izz="7.98191938878511E-06" />
    </inertial>
    <visual>
      <origin
        xyz="0 0 0"
        rpy="0 0 0" />
      <geometry>
        <mesh
          filename="package://robotic_arm_6dof/meshes/shoulder_link.STL" />
      </geometry>
      <material
        name="">
        <color
          rgba="0.792156862745098 0.819607843137255 0.933333333333333 1" />
      </material>
    </visual>
    <collision>
      <origin
        xyz="0 0 0"
        rpy="0 0 0" />
      <geometry>
        <mesh
          filename="package://robotic_arm_6dof/meshes/shoulder_link.STL" />
      </geometry>
    </collision>
  </link>
  <joint
    name="shoulder_joint"
    type="revolute">
    <origin
      xyz="0.001501 -0.0236 0.0201"
      rpy="0.12148 -0.43402 -0.28254" />
    <parent
      link="base_rotator" />
    <child
      link="shoulder_link" />
    <axis
      xyz="-0.25294 0.96748 0" />
    <limit
      lower="-1.57"
      upper="1.57"
      effort="0"
      velocity="0" />
  </joint>
  <link
    name="elbow_Link">
    <inertial>
      <origin
        xyz="0.0179850825088401 0.0231349067362636 -0.000816047063876363"
        rpy="0 0 0" />
      <mass
        value="0.0420586657729736" />
      <inertia
        ixx="9.19057415809374E-06"
        ixy="-2.07862091149447E-08"
        ixz="-8.86211668419417E-08"
        iyy="8.80316220324554E-06"
        iyz="-7.91496258450743E-08"
        izz="1.49766403640064E-05" />
    </inertial>
    <visual>
      <origin
        xyz="0 0 0"
        rpy="0 0 0" />
      <geometry>
        <mesh
          filename="package://robotic_arm_6dof/meshes/elbow_Link.STL" />
      </geometry>
      <material
        name="">
        <color
          rgba="0.792156862745098 0.819607843137255 0.933333333333333 1" />
      </material>
    </visual>
    <collision>
      <origin
        xyz="0 0 0"
        rpy="0 0 0" />
      <geometry>
        <mesh
          filename="package://robotic_arm_6dof/meshes/elbow_Link.STL" />
      </geometry>
    </collision>
  </link>
  <joint
    name="elbow_joint"
    type="revolute">
    <origin
      xyz="-0.000720890128520002 0.0027573206963649 0.103"
      rpy="0.109466615902697 -0.677396307197321 0.0821328070422031" />
    <parent
      link="shoulder_link" />
    <child
      link="elbow_Link" />
    <axis
      xyz="-0.134583598084368 0.990902242971861 0" />
    <limit
      lower="-1.57"
      upper="1.57"
      effort="0"
      velocity="0" />
  </joint>
  <link
    name="wrist_Link">
    <inertial>
      <origin
        xyz="0.0201661642819521 0.0185253919729509 0.0134765430950954"
        rpy="0 0 0" />
      <mass
        value="0.0644141323115809" />
      <inertia
        ixx="1.0619854325748E-05"
        ixy="-1.43463626130247E-07"
        ixz="6.65104745661783E-08"
        iyy="1.06200186270456E-05"
        iyz="6.65111783188749E-08"
        izz="1.71013472797244E-05" />
    </inertial>
    <visual>
      <origin
        xyz="0 0 0"
        rpy="0 0 0" />
      <geometry>
        <mesh
          filename="package://robotic_arm_6dof/meshes/wrist_Link.STL" />
      </geometry>
      <material
        name="">
        <color
          rgba="0.792156862745098 0.819607843137255 0.933333333333333 1" />
      </material>
    </visual>
    <collision>
      <origin
        xyz="0 0 0"
        rpy="0 0 0" />
      <geometry>
        <mesh
          filename="package://robotic_arm_6dof/meshes/wrist_Link.STL" />
      </geometry>
    </collision>
  </link>
  <joint
    name="wrist_joint"
    type="revolute">
    <origin
      xyz="0.0957085548832958 0.0123430961736119 0.00149999999999995"
      rpy="0 1.15689373274673 0.134993225634174" />
    <parent
      link="elbow_Link" />
    <child
      link="wrist_Link" />
    <axis
      xyz="0 1 0" />
    <limit
      lower="-1.57"
      upper="1.57"
      effort="0"
      velocity="0" />
  </joint>
  <link
    name="end_base">
    <inertial>
      <origin
        xyz="0.0291048300694188 -0.0219227058945996 -0.0182001290221276"
        rpy="0 0 0" />
      <mass
        value="0.0345345547168646" />
      <inertia
        ixx="8.00021100531572E-06"
        ixy="4.63252693135927E-09"
        ixz="4.00541184882921E-13"
        iyy="4.78420683454556E-06"
        iyz="-7.17154389145337E-08"
        izz="5.91653043542266E-06" />
    </inertial>
    <visual>
      <origin
        xyz="0 0 0"
        rpy="0 0 0" />
      <geometry>
        <mesh
          filename="package://robotic_arm_6dof/meshes/end_base.STL" />
      </geometry>
      <material
        name="">
        <color
          rgba="0.792156862745098 0.819607843137255 0.933333333333333 1" />
      </material>
    </visual>
    <collision>
      <origin
        xyz="0 0 0"
        rpy="0 0 0" />
      <geometry>
        <mesh
          filename="package://robotic_arm_6dof/meshes/end_base.STL" />
      </geometry>
    </collision>
  </link>
  <joint
    name="end_joint"
    type="revolute">
    <origin
      xyz="0.0545990000041253 0.0259989999957502 0.0269999999957503"
      rpy="0.0529233606550124 0 0" />
    <parent
      link="wrist_Link" />
    <child
      link="end_base" />
    <axis
      xyz="-1 0 0" />
    <limit
      lower="-1.57"
      upper="1.57"
      effort="0"
      velocity="0" />
  </joint>
  <link
    name="gear_right">
    <inertial>
      <origin
        xyz="0.00522210775020111 0.000121761120217403 0.000637835367012118"
        rpy="0 0 0" />
      <mass
        value="0.00207956891883696" />
      <inertia
        ixx="6.18312305314825E-08"
        ixy="2.9040733035334E-09"
        ixz="-1.07678319362615E-12"
        iyy="2.47299851403229E-07"
        iyz="4.77479240020125E-12"
        izz="3.06156104591973E-07" />
    </inertial>
    <visual>
      <origin
        xyz="0 0 0"
        rpy="0 0 0" />
      <geometry>
        <mesh
          filename="package://robotic_arm_6dof/meshes/gear_right.STL" />
      </geometry>
      <material
        name="">
        <color
          rgba="0.792156862745098 0.819607843137255 0.933333333333333 1" />
      </material>
    </visual>
    <collision>
      <origin
        xyz="0 0 0"
        rpy="0 0 0" />
      <geometry>
        <mesh
          filename="package://robotic_arm_6dof/meshes/gear_right.STL" />
      </geometry>
    </collision>
  </link>
  <joint
    name="gear_right_joint"
    type="revolute">
    <origin
      xyz="0.03 -0.015741 0.0043"
      rpy="0 0 -0.60373" />
    <parent
      link="end_base" />
    <child
      link="gear_right" />
    <axis
      xyz="0 0 -1" />
    <limit
      lower="-1.57"
      upper="1.57"
      effort="0"
      velocity="0" />
  </joint>
  <link
    name="finger_right">
    <inertial>
      <origin
        xyz="0.0222749786582408 -0.00229862724332237 -0.00449696732193056"
        rpy="0 0 0" />
      <mass
        value="0.00221856156382406" />
      <inertia
        ixx="3.8168362729864E-08"
        ixy="9.48550472979781E-08"
        ixz="-1.55713868214021E-13"
        iyy="5.21693961792075E-07"
        iyz="1.51260953346411E-16"
        izz="5.52361046133005E-07" />
    </inertial>
    <visual>
      <origin
        xyz="0 0 0"
        rpy="0 0 0" />
      <geometry>
        <mesh
          filename="package://robotic_arm_6dof/meshes/finger_right.STL" />
      </geometry>
      <material
        name="">
        <color
          rgba="0.792156862745098 0.819607843137255 0.933333333333333 1" />
      </material>
    </visual>
    <collision>
      <origin
        xyz="0 0 0"
        rpy="0 0 0" />
      <geometry>
        <mesh
          filename="package://robotic_arm_6dof/meshes/finger_right.STL" />
      </geometry>
    </collision>
  </link>
  <joint
    name="finger_right_joint"
    type="revolute">
    <origin
      xyz="0.030762 0 0.0025"
      rpy="0 0 0.98133" />
    <parent
      link="gear_right" />
    <child
      link="finger_right" />
    <axis
      xyz="0 0 1" />
    <limit
      lower="-1.57"
      upper="1.57"
      effort="0"
      velocity="0" />
    <mimic
      joint="gear_right_joint"
      multiplier="1"
      offset="0" />
  </joint>
  <link
    name="gear_left">
    <inertial>
      <origin
        xyz="0.00742875873647911 -0.000173281374520518 -0.0011045371319465"
        rpy="0 0 0" />
      <mass
        value="0.00146187481822585" />
      <inertia
        ixx="4.66933745433603E-08"
        ixy="-2.78602520296168E-09"
        ixz="1.81888424446724E-12"
        iyy="2.37227324448417E-07"
        iyz="-4.73125416228374E-12"
        izz="2.82953106359871E-07" />
    </inertial>
    <visual>
      <origin
        xyz="0 0 0"
        rpy="0 0 0" />
      <geometry>
        <mesh
          filename="package://robotic_arm_6dof/meshes/gear_left.STL" />
      </geometry>
      <material
        name="">
        <color
          rgba="0.792156862745098 0.819607843137255 0.933333333333333 1" />
      </material>
    </visual>
    <collision>
      <origin
        xyz="0 0 0"
        rpy="0 0 0" />
      <geometry>
        <mesh
          filename="package://robotic_arm_6dof/meshes/gear_left.STL" />
      </geometry>
    </collision>
  </link>
  <joint
    name="gear_left_joint"
    type="revolute">
    <origin
      xyz="0.0305 0.01226 0.0068"
      rpy="0 0 0.3732" />
    <parent
      link="end_base" />
    <child
      link="gear_left" />
    <axis
      xyz="0 0 -1" />
    <limit
      lower="-1.57"
      upper="1.57"
      effort="0"
      velocity="0" />
    <mimic
      joint="gear_right_joint"
      multiplier="-1"
      offset="0" />
  </joint>
  <link
    name="finger_left">
    <inertial>
      <origin
        xyz="0.0224117829979157 0.00231258624567058 -0.00446850609130195"
        rpy="0 0 0" />
      <mass
        value="0.00220506613383814" />
      <inertia
        ixx="3.77773345499567E-08"
        ixy="-9.48534895099289E-08"
        ixz="2.72215152298512E-13"
        iyy="5.21302462663036E-07"
        iyz="-1.42086394163337E-14"
        izz="5.52347265627548E-07" />
    </inertial>
    <visual>
      <origin
        xyz="0 0 0"
        rpy="0 0 0" />
      <geometry>
        <mesh
          filename="package://robotic_arm_6dof/meshes/finger_left.STL" />
      </geometry>
      <material
        name="">
        <color
          rgba="0.792156862745098 0.819607843137255 0.933333333333333 1" />
      </material>
    </visual>
    <collision>
      <origin
        xyz="0 0 0"
        rpy="0 0 0" />
      <geometry>
        <mesh
          filename="package://robotic_arm_6dof/meshes/finger_left.STL" />
      </geometry>
    </collision>
  </link>
  <joint
    name="finger_left_joint"
    type="revolute">
    <origin
      xyz="0.030762 0 0"
      rpy="0 0 -0.68869" />
    <parent
      link="gear_left" />
    <child
      link="finger_left" />
    <axis
      xyz="0 0 1" />
    <limit
      lower="-1.57"
      upper="1.57"
      effort="0"
      velocity="0" />
    <mimic
      joint="gear_left_joint"
      multiplier="1"
      offset="0" />
  </joint>
  <link
    name="anchor_right">
    <inertial>
      <origin
        xyz="0.0149999999772549 2.32300290115006E-13 -0.00520000000000004"
        rpy="0 0 0" />
      <mass
        value="0.00040273621239968" />
      <inertia
        ixx="7.10894577642955E-10"
        ixy="4.82734850667704E-19"
        ixz="2.3164769576848E-17"
        iyy="4.947065575232E-08"
        iyz="-1.16657004682848E-17"
        izz="4.99214388440103E-08" />
    </inertial>
    <visual>
      <origin
        xyz="0 0 0"
        rpy="0 0 0" />
      <geometry>
        <mesh
          filename="package://robotic_arm_6dof/meshes/anchor_right.STL" />
      </geometry>
      <material
        name="">
        <color
          rgba="0.792156862745098 0.819607843137255 0.933333333333333 1" />
      </material>
    </visual>
    <collision>
      <origin
        xyz="0 0 0"
        rpy="0 0 0" />
      <geometry>
        <mesh
          filename="package://robotic_arm_6dof/meshes/anchor_right.STL" />
      </geometry>
    </collision>
  </link>
  <joint
    name="anchor_right_joint"
    type="revolute">
    <origin
      xyz="0.0525 -0.007 0.0068"
      rpy="0 0 -0.6321" />
    <parent
      link="end_base" />
    <child
      link="anchor_right" />
    <axis
      xyz="0 0 -1" />
    <limit
      lower="-1.57"
      upper="1.57"
      effort="0"
      velocity="0" />
    <mimic
      joint="gear_right_joint"
      multiplier="1"
      offset="0" />
  </joint>
  <link
    name="anchor_left">
    <inertial>
      <origin
        xyz="0.0149999999555894 3.27828042490097E-14 -0.00520000000000001"
        rpy="0 0 0" />
      <mass
        value="0.000402736212399681" />
      <inertia
        ixx="7.10894577224504E-10"
        ixy="-2.91276563126718E-20"
        ixz="2.28948117330554E-18"
        iyy="4.94706557524056E-08"
        iyz="-2.27182309736382E-17"
        izz="4.99214388436773E-08" />
    </inertial>
    <visual>
      <origin
        xyz="0 0 0"
        rpy="0 0 0" />
      <geometry>
        <mesh
          filename="package://robotic_arm_6dof/meshes/anchor_left.STL" />
      </geometry>
      <material
        name="">
        <color
          rgba="0.792156862745098 0.819607843137255 0.933333333333333 1" />
      </material>
    </visual>
    <collision>
      <origin
        xyz="0 0 0"
        rpy="0 0 0" />
      <geometry>
        <mesh
          filename="package://robotic_arm_6dof/meshes/anchor_left.STL" />
      </geometry>
    </collision>
  </link>
  <joint
    name="anchor_left_joint"
    type="revolute">
    <origin
      xyz="0.0525 0.007 0.0068"
      rpy="0 0 0.31658" />
    <parent
      link="end_base" />
    <child
      link="anchor_left" />
    <axis
      xyz="0 0 -1" />
    <limit
      lower="-1.57"
      upper="1.57"
      effort="0"
      velocity="0" />
    <mimic
      joint="gear_left_joint"
      multiplier="1"
      offset="0" />
  </joint>
</robot>